<?xml version="1.0"?>
<robot xmlns:xacro="http://www.ros.org/wiki/xacro" name="manipulator">

  <xacro:include filename="$(find manipulator_description)/urdf/manipulator.ros2_control.xacro"/>
  
  <link name="base_link"></link>
    
  <joint name="joint0" type="continuous">
    <parent link="base_link"/>
    <child link="link1"/>
    <origin xyz="0.05 0 0.088" rpy="0 0 0" />
    <axis xyz="0 0 1" />
    <limit effort="0.5" velocity="6.0" />
  </joint>

  <link name="link1"></link>

  <joint name="joint1" type="continuous">
    <parent link="link1"/>
    <child link="camera_link"/>
    <origin xyz="0 0 0.086" rpy="0 0 0" />
    <axis xyz="0 1 0" />
    <limit effort="0.5" velocity="6.0" />
    <friction friction="0.01" />
    <dynamics damping="0.4" />
  </joint>

   <link name="camera_link">
    <visual>
      <origin xyz="0 0 0.0125" rpy="0 0 0" />
      <geometry>
        <box size="0.05 0.045 0.025" />
      </geometry>
      <material name="red">
        <color rgba=".8 0 0 1" />
      </material>
    </visual>
  </link>

  <xacro:property name="NAME_JOINT_0" value="joint0"/>
  <xacro:property name="NAME_JOINT_1" value="joint1"/>
  <xacro:property name="JOINT_0_LOWER_LIMIT" value="-70"/>
  <xacro:property name="JOINT_0_UPPER_LIMIT" value="70"/>
  <xacro:property name="JOINT_1_LOWER_LIMIT" value="-70"/>
  <xacro:property name="JOINT_1_UPPER_LIMIT" value="70"/>  

  <xacro:manipulator_ros2_control_settings 
    name="manipulator"
    name_joint_0="${NAME_JOINT_0}"
    name_joint_1="${NAME_JOINT_1}"
    joint_0_lower_limit="${JOINT_0_LOWER_LIMIT}"
    joint_0_upper_limit="${JOINT_0_UPPER_LIMIT}"
    joint_1_lower_limit="${JOINT_1_LOWER_LIMIT}"
    joint_1_upper_limit="${JOINT_1_UPPER_LIMIT}" />

</robot>
