<?xml version="1.0"?>
<robot name="camera_mount">

  <link name="base_link"></link>
    
  <joint name="joint0" type="continuous">
    <parent link="base_link"/>
    <child link="link1"/>
    <origin xyz="0.05 0 0.088" rpy="0 0 0" />
    <axis xyz="0 0 1" />
    <limit effort="0.5" velocity="6.0" />
  </joint>

  <link name="link1"></link>

  <joint name="joint1" type="continuous">
    <parent link="link1"/>
    <child link="camera_link"/>
    <origin xyz="0 0 0.086" rpy="0 0 0" />
    <axis xyz="0 1 0" />
    <limit effort="0.5" velocity="6.0" />
    <friction friction="0.01" />
    <dynamics damping="0.4" />
  </joint>

   <link name="camera_link">
    <visual>
      <origin xyz="0 0 0.0125" rpy="0 0 0" />
      <geometry>
        <box size="0.05 0.045 0.025" />
      </geometry>
      <material name="red">
        <color rgba=".8 0 0 1" />
      </material>
    </visual>
  </link>

</robot>
